<mujoco model="craft_hand">
    <compiler angle="degree"/>
    <visual>
        <global offwidth="1920" offheight="1080"/>
        <quality shadowsize="4096" offsamples="8"/>
        <map znear="0.001" zfar="10"/>
    </visual>

    <default>
        <!-- convert the Fusion 360 coordinate system to MuJoCo -->
        <geom type="mesh" xyaxes="1 0 0 0 0 1"/>
        <joint armature="0.01"/>
    </default>
    <asset>
        <!-- Checkerboard floor texture -->
        <texture name="grid" type="2d" builtin="checker" width="2048" height="2048" rgb1="0.1 0.2 0.3" rgb2="0.2 0.3 0.4"/>
        <material name="grid" texture="grid" texrepeat="8 8" reflectance="0.2"/>
        <!-- Tennis ball texture -->
        <texture name="tennis" type="2d" builtin="flat" width="512" height="512" rgb1="1.0 1.0 0.0" rgb2="1.0 1.0 0.0"/>
        <material name="tennis" texture="tennis" texuniform="true" reflectance="0.05"/>
        <!-- Fusion outputs meshes with mm units by default, but must be converted to m in MuJoCo, hence the scaling -->
        <mesh name="base" file="base.stl" scale="0.001 0.001 0.001"/>
        <mesh name="index1" file="index1.stl" scale="0.001 0.001 0.001"/>
        <mesh name="index2" file="index2.stl" scale="0.001 0.001 0.001"/>
        <mesh name="index3" file="index3.stl" scale="0.001 0.001 0.001"/>
        <mesh name="index4" file="index4.stl" scale="0.001 0.001 0.001"/>
        <mesh name="middle1" file="middle1.stl" scale="0.001 0.001 0.001"/>
        <mesh name="middle2" file="middle2.stl" scale="0.001 0.001 0.001"/>
        <mesh name="middle3" file="middle3.stl" scale="0.001 0.001 0.001"/>
        <mesh name="middle4" file="middle4.stl" scale="0.001 0.001 0.001"/>
        <mesh name="ring1" file="ring1.stl" scale="0.001 0.001 0.001"/>
        <mesh name="ring2" file="ring2.stl" scale="0.001 0.001 0.001"/>
        <mesh name="ring3" file="ring3.stl" scale="0.001 0.001 0.001"/>
        <mesh name="ring4" file="ring4.stl" scale="0.001 0.001 0.001"/>
        <mesh name="pinky1" file="pinky1.stl" scale="0.001 0.001 0.001"/>
        <mesh name="pinky2" file="pinky2.stl" scale="0.001 0.001 0.001"/>
        <mesh name="pinky3" file="pinky3.stl" scale="0.001 0.001 0.001"/>
        <mesh name="pinky4" file="pinky4.stl" scale="0.001 0.001 0.001"/>
        <mesh name="thumbmcp" file="ThumbMCP.stl" scale="0.001 0.001 0.001"/>
        <mesh name="thumb2" file="thumb2.stl" scale="0.001 0.001 0.001"/>
        <mesh name="thumb3" file="thumb3.stl" scale="0.001 0.001 0.001"/>
        <mesh name="thumb4" file="thumb4.stl" scale="0.001 0.001 0.001"/>
    </asset>

z    <worldbody>
        <light pos="0 -0.5 0.5" dir="0 1 -0.5" diffuse="1 1 1"/>
        <geom name="floor" type="plane" size="0.5 0.5 0.01" rgba="0.9 0.9 0.9 1" material="grid"/>
        <camera name="front" pos="0 -0.45 -0.3" xyaxes="1 0 0 0 -0.5 1"/>
        <camera name="top" pos="0 -0.05 0.3" xyaxes="1 0 0 0 -1 0"/>
        <camera name="side" pos="0.4 -0.1 -0.1" xyaxes="0 -1 0 0 0 1"/>
        <!-- Cube on palm -->
        <!-- Tennis ball on palm -->
        <body name="ball" pos="0.02 -0.12 -0.08">
            <freejoint/>
            <geom type="sphere" size="0.028" material="tennis" mass="0.057"/>
        </body>
        <body name="base">
            <geom mesh="base"/>
            <!-- Index finger -->
            <body name="index1">
                <joint name="index_1" pos="-0.008969 -0.092739 -0.068253" axis="0 1 0" limited="true" range="-45 45"/>
                <geom mesh="index1"/>
                <body name="index2">
                    <joint name="index_2" pos="-0.0139 -0.0821 -0.0862" axis="-1 0 0" limited="true" range="0 90"/>
                    <geom mesh="index2"/>
                    <body name="index3">
                        <joint name="index_3" pos="-0.016077 -0.086888 -0.131325" axis="-1 0 0" limited="true" range="0 110"/>
                        <geom mesh="index3"/>
                        <body name="index4">
                            <joint name="index_4" pos="-0.0161 -0.0869 -0.1547" axis="-1 0 0" limited="true" range="0 110"/>
                            <geom mesh="index4"/>
                        </body>
                    </body>
                </body>
            </body>
            <!-- Middle finger -->
            <body name="middle1">
                <joint name="middle_1" pos="0.012 -0.0927 -0.0783" axis="0 1 0" limited="true" range="-45 45"/>
                <geom mesh="middle1"/>
                <body name="middle2">
                    <joint name="middle_2" pos="0.0085 -0.0821 -0.0962" axis="-1 0 0" limited="true" range="0 90"/>
                    <geom mesh="middle2"/>
                    <body name="middle3">
                        <joint name="middle_3" pos="0.0107 -0.0859 -0.142" axis="-1 0 0" limited="true" range="0 110"/>
                        <geom mesh="middle3"/>
                        <body name="middle4">
                            <joint name="middle_4" pos="0.0107 -0.0859 -0.164" axis="-1 0 0" limited="true" range="0 110"/>
                            <geom mesh="middle4"/>
                        </body>
                    </body>
                </body>
            </body>
            <!-- Ring finger -->
            <body name="ring1">
                <joint name="ring_1" pos="0.033 -0.0927 -0.0683" axis="0 1 0" limited="true" range="-45 45"/>
                <geom mesh="ring1"/>
                <body name="ring2">
                    <joint name="ring_2" pos="0.0293 -0.0821 -0.0862" axis="-1 0 0" limited="true" range="0 90"/>
                    <geom mesh="ring2"/>
                    <body name="ring3">
                        <joint name="ring_3" pos="0.0301 -0.0859 -0.132" axis="-1 0 0" limited="true" range="0 110"/>
                        <geom mesh="ring3"/>
                        <body name="ring4">
                            <joint name="ring_4" pos="0.0315 -0.0859 -0.154" axis="-1 0 0" limited="true" range="0 110"/>
                            <geom mesh="ring4"/>
                        </body>
                    </body>
                </body>
            </body>
            <!-- Pinky finger -->
            <body name="pinky1">
                <joint name="pinky_1" pos="0.054 -0.0927 -0.0583" axis="0 1 0" limited="true" range="-45 45"/>
                <geom mesh="pinky1"/>
                <body name="pinky2">
                    <joint name="pinky_2" pos="0.0574 -0.0821 -0.0762" axis="-1 0 0" limited="true" range="0 90"/>
                    <geom mesh="pinky2"/>
                    <body name="pinky3">
                        <joint name="pinky_3" pos="0.0525 -0.0859 -0.122" axis="-1 0 0" limited="true" range="0 110"/>
                        <geom mesh="pinky3"/>
                        <body name="pinky4">
                            <joint name="pinky_4" pos="0.0525 -0.0859 -0.144" axis="-1 0 0" limited="true" range="0 110"/>
                            <geom mesh="pinky4"/>
                        </body>
                    </body>
                </body>
            </body>
            <!-- Thumb -->
            <body name="thumbmcp">
                <joint name="thumb_mcp" pos="0.006 -0.092 -0.029" axis="-0.57 0 -0.82" limited="true" range="-170 0"/>
                <geom mesh="thumbmcp"/>
                <body name="thumb2">
                    <joint name="thumb_2" pos="-0.013 -0.100 -0.022" axis="0 1 0" limited="true" range="0 90"/>
                    <geom mesh="thumb2"/>
                    <body name="thumb3">
                        <joint name="thumb_3" pos="-0.034 -0.098 -0.063" axis="-0.47 -0.82 0.33" limited="true" range="0 110"/>
                        <geom mesh="thumb3"/>
                        <body name="thumb4">
                            <joint name="thumb_4" pos="-0.047 -0.096 -0.081" axis="-0.48 -0.84 0.27" limited="true" range="0 110"/>
                            <geom mesh="thumb4"/>
                        </body>
                    </body>
                </body>
            </body>
        </body>
    </worldbody>

    <contact>
        <!-- Index finger exclusions -->
        <exclude body1="base" body2="index1"/>
        <exclude body1="index1" body2="index2"/>
        <exclude body1="index2" body2="index3"/>
        <exclude body1="index3" body2="index4"/>
        <!-- Middle finger exclusions -->
        <exclude body1="base" body2="middle1"/>
        <exclude body1="middle1" body2="middle2"/>
        <exclude body1="middle2" body2="middle3"/>
        <exclude body1="middle3" body2="middle4"/>
        <!-- Ring finger exclusions -->
        <exclude body1="base" body2="ring1"/>
        <exclude body1="ring1" body2="ring2"/>
        <exclude body1="ring2" body2="ring3"/>
        <exclude body1="ring3" body2="ring4"/>
        <!-- Pinky finger exclusions -->
        <exclude body1="base" body2="pinky1"/>
        <exclude body1="pinky1" body2="pinky2"/>
        <exclude body1="pinky2" body2="pinky3"/>
        <exclude body1="pinky3" body2="pinky4"/>
        <!-- Thumb exclusions -->
        <exclude body1="base" body2="thumbmcp"/>
        <exclude body1="thumbmcp" body2="thumb2"/>
        <exclude body1="thumb2" body2="thumb3"/>
        <exclude body1="thumb3" body2="thumb4"/>
    </contact>

    <equality>
        <!-- Joint 4 mirrors Joint 3 for each finger -->
        <joint joint1="index_3" joint2="index_4" polycoef="0 1 0 0 0"/>
        <joint joint1="middle_3" joint2="middle_4" polycoef="0 1 0 0 0"/>
        <joint joint1="ring_3" joint2="ring_4" polycoef="0 1 0 0 0"/>
        <joint joint1="pinky_3" joint2="pinky_4" polycoef="0 1 0 0 0"/>
        <joint joint1="thumb_3" joint2="thumb_4" polycoef="0 1 0 0 0"/>
    </equality>

    <actuator>
        <!-- Index finger -->
        <position name="index_1" joint="index_1" ctrllimited="true" ctrlrange="-45 45" kp="0.5" kv="0.1"/>
        <position name="index_2" joint="index_2" ctrllimited="true" ctrlrange="0 90" kp="0.5" kv="0.1"/>
        <position name="index_3" joint="index_3" ctrllimited="true" ctrlrange="0 110" kp="0.1" kv="0.1"/>
        <!-- Middle finger -->
        <position name="middle_1" joint="middle_1" ctrllimited="true" ctrlrange="-45 45" kp="0.5" kv="0.1"/>
        <position name="middle_2" joint="middle_2" ctrllimited="true" ctrlrange="0 90" kp="0.5" kv="0.1"/>
        <position name="middle_3" joint="middle_3" ctrllimited="true" ctrlrange="0 110" kp="0.1" kv="0.1"/>
        <!-- Ring finger -->
        <position name="ring_1" joint="ring_1" ctrllimited="true" ctrlrange="-45 45" kp="0.5" kv="0.1"/>
        <position name="ring_2" joint="ring_2" ctrllimited="true" ctrlrange="0 90" kp="0.5" kv="0.1"/>
        <position name="ring_3" joint="ring_3" ctrllimited="true" ctrlrange="0 110" kp="0.1" kv="0.1"/>
        <!-- Pinky finger -->
        <position name="pinky_1" joint="pinky_1" ctrllimited="true" ctrlrange="-45 45" kp="0.5" kv="0.1"/>
        <position name="pinky_2" joint="pinky_2" ctrllimited="true" ctrlrange="0 90" kp="0.5" kv="0.1"/>
        <position name="pinky_3" joint="pinky_3" ctrllimited="true" ctrlrange="0 110" kp="0.1" kv="0.1"/>
        <!-- Thumb -->
        <position name="thumb_mcp" joint="thumb_mcp" ctrllimited="true" ctrlrange="-45 45" kp="0.5" kv="0.1"/>
        <position name="thumb_2" joint="thumb_2" ctrllimited="true" ctrlrange="0 90" kp="0.5" kv="0.1"/>
        <position name="thumb_3" joint="thumb_3" ctrllimited="true" ctrlrange="0 110" kp="0.1" kv="0.1"/>
    </actuator>
</mujoco>